<?xml version="1.0"?>
<robot xmlns:xacro="http://ros.org/wiki/xacro" name="simple_robot">

  <!-- Properties -->
  <xacro:property name="body_length" value="1.3"/>
  <xacro:property name="body_width"  value="0.8"/>
  <xacro:property name="body_height" value="0.2"/>

  <xacro:property name="wheel_radius" value="0.15"/>
  <xacro:property name="wheel_width"  value="0.06"/>
  <xacro:property name="wheel_offset_x" value="0.65"/>
  <xacro:property name="wheel_offset_y" value="0.4"/>

  <!-- Robot Base Link -->
  <link name="base_link">
    <visual>
      <origin xyz="0 0 ${body_height/2}" rpy="0 0 0"/>
      <geometry>
        <box size="${body_length} ${body_width} ${body_height}"/>
      </geometry>
      <material name="Red">
        <color rgba="1 0 0 1"/>
      </material>
    </visual>
    <collision>
      <origin xyz="0 0 ${body_height/2}" rpy="0 0 0"/>
      <geometry>
        <box size="${body_length} ${body_width} ${body_height}"/>
      </geometry>
    </collision>
    <inertial>
      <mass value="20.0"/>
      <inertia ixx="1.0" ixy="0.0" ixz="0.0" iyy="1.0" iyz="0.0" izz="1.0"/>
      <origin xyz="0 0 ${body_height/2}" rpy="0 0 0"/>
    </inertial>
  </link>

  <!-- Left Wheel -->
  <link name="left_wheel">
    <visual>
      <origin xyz="0 0 0" rpy="0 1.5708 0"/>
      <geometry>
        <cylinder radius="${wheel_radius}" length="${wheel_width}"/>
      </geometry>
      <material name="Blue">
        <color rgba="0 0 1 1"/>
      </material>
    </visual>
  </link>

  <joint name="left_wheel_joint" type="continuous">
    <parent link="base_link"/>
    <child link="left_wheel"/>
    <origin xyz="${-wheel_offset_x} ${wheel_offset_y} 0" rpy="0 0 0"/>
    <axis xyz="0 1 0"/>
  </joint>

  <!-- Right Wheel -->
  <link name="right_wheel">
    <visual>
      <origin xyz="0 0 0" rpy="0 1.5708 0"/>
      <geometry>
        <cylinder radius="${wheel_radius}" length="${wheel_width}"/>
      </geometry>
      <material name="Blue"/>
    </visual>
  </link>

  <joint name="right_wheel_joint" type="continuous">
    <parent link="base_link"/>
    <child link="right_wheel"/>
    <origin xyz="${wheel_offset_x} ${wheel_offset_y} 0" rpy="0 0 0"/>
    <axis xyz="0 1 0"/>
  </joint>

</robot>
